<?xml version="1.0" ?>
<!-- =================================================================================== -->
<!-- |    This document was autogenerated by xacro from guardian_tracks.urdf.xacro     | -->
<!-- |    EDITING THIS FILE BY HAND IS NOT RECOMMENDED                                 | -->
<!-- =================================================================================== -->
<robot name="guardian" xmlns:xacro="http://www.ros.org/wiki/xacro">
  <gazebo>
    <plugin filename="libgazebo_ros_control.so" name="ros_control">
      <robotNamespace>/guardian</robotNamespace>
      <controlPeriod>0.001</controlPeriod>
      <robotSimType>gazebo_ros_control/DefaultRobotHWSim</robotSimType>
    </plugin>
  </gazebo>
  <gazebo>
    <plugin filename="libgazebo_ros_p3d.so" name="ground_truth">
      <bodyName>base_footprint</bodyName>
      <topicName>/guardian/base_pose_ground_truth</topicName>
      <frameName>map</frameName>
      <updateRate>0.0</updateRate>
      <!-- max possible rate -->
    </plugin>
  </gazebo>
  <gazebo reference="base_footprint">
    <material>Gazebo/Green</material>
  </gazebo>
  <gazebo reference="base_link">
    <material>Gazebo/Grey</material>
    <turnGravityOff>false</turnGravityOff>
  </gazebo>
  <material name="Schunk/LightGrey">
    <color rgba="0.7 0.7 0.7 1.0"/>
  </material>
  <material name="Schunk/DarkGrey">
    <color rgba="0.4 0.4 0.4 1.0"/>
  </material>
  <material name="Schunk/Black">
    <color rgba="0.0 0.0 0.0 1.0"/>
  </material>
  <material name="Schunk/DarkGolden">
    <color rgba="0.4 0.4 0.3 1.0"/>
  </material>
  <material name="Schunk/Blue">
    <color rgba="0.0 0.0 0.8 1.0"/>
  </material>
  <gazebo>
    <plugin filename="libgazebo_ros_control.so" name="ros_control">
      <!--robotNamespace>/</robotNamespace-->
      <!--robotSimType>gazebo_ros_control/DefaultRobotHWSim</robotSimType-->
    </plugin>
  </gazebo>
  <!-- ###### BASE ###### -->
  <link name="base_footprint">
    <visual>
      <origin rpy="0 0 0" xyz="0 0 0"/>
      <geometry>
        <box size="0.005 0.005 0.005"/>
      </geometry>
    </visual>
  </link>
  <joint name="base_footprint_joint" type="fixed">
    <!--NB: While you would think this would make it go up, it is oddly reversed. This moves the joint to 0,0,0 where we want it for rviz, etc. -->
    <!-- <origin xyz="0 0 0.130" rpy="0 0 0" /> -->
    <!-- <origin xyz="0 0 0.18" rpy="0 0 0" /> -->
    <origin rpy="0 0 0" xyz="0 0 0.0635"/>
    <parent link="base_footprint"/>
    <child link="base_link"/>
  </joint>
  <link name="support_bottom_link"/>
  <joint name="support_bottom_joint" type="fixed">
    <origin rpy="0 0 0" xyz="0.185 0 0.2425"/>
    <parent link="base_link"/>
    <child link="support_bottom_link"/>
  </joint>
  <link name="support_top_link"/>
  <joint name="support_top_joint" type="fixed">
    <origin rpy="0.0 0 0.0" xyz="0.314 0.0 0.256"/>
    <parent link="support_bottom_link"/>
    <child link="support_top_link"/>
  </joint>
  <link name="base_link">
    <!-- center of wheels -> rotation axis -->
    <inertial>
      <mass value="95.0"/>
      <!-- 95.0 -->
      <origin xyz="0 0 0"/>
      <inertia ixx="3.737" ixy="0.008" ixz="-0.144" iyy="8.311" iyz="-0.004" izz="8.893"/>
    </inertial>
    <visual>
      <origin rpy="0 0 0" xyz="0 0 0"/>
      <geometry>
        <mesh filename="package://guardian_description/meshes/chassis/two_lasers/guardian2lasers.stl"/>
      </geometry>
      <material name="DarkGrey">
        <color rgba="0.4 0.4 0.4 1.0"/>
      </material>
    </visual>
    <collision>
      <origin rpy="0 0 0 " xyz="0 0 0.08"/>
      <geometry>
        <!-- <box size = "1.127 0.497 0.28"/> -->
        <!-- includes tracks, making it just tall enough not to hit the laser beams -->
        <box size="1.127 0.497 0.25"/>
        <!-- this is not enough -->
      </geometry>
    </collision>
  </link>
  <link name="arm_link">
    <visual>
      <origin rpy="0 0 0" xyz="0 0 0"/>
      <geometry>
        <cylinder length="0.001" radius="0.001"/>
      </geometry>
    </visual>
  </link>
  <joint name="arm_joint" type="fixed">
    <parent link="base_link"/>
    <child link="arm_link"/>
    <origin rpy="0 0 0" xyz="0.15 0 -0.13"/>
  </joint>
  <joint name="arm_0_joint" type="fixed">
    <origin rpy="0 0 0" xyz="0.0 0 0.5"/>
    <parent link="arm_link"/>
    <child link="arm_0_link"/>
  </joint>
  <link name="arm_0_link">
    <inertial>
      <origin rpy="0 0 0" xyz="0 0 0"/>
      <mass value="0.29364"/>
      <inertia ixx="0.01" ixy="0" ixz="0" iyy="0.01" iyz="0" izz="0.01"/>
    </inertial>
    <visual>
      <origin rpy="0 0 0" xyz="0 0 0"/>
      <geometry>
        <mesh filename="package://schunk_description/meshes/lwa4p/arm_0_link.stl"/>
      </geometry>
      <material name="Schunk/LightGrey"/>
    </visual>
    <collision>
      <origin rpy="0 0 0" xyz="0 0 0"/>
      <geometry>
        <mesh filename="package://schunk_description/meshes/lwa4p/arm_0_link.stl"/>
      </geometry>
    </collision>
  </link>
  <joint name="arm_1_joint" type="revolute">
    <origin rpy="0 0 0" xyz="0 0 0.11"/>
    <parent link="arm_0_link"/>
    <child link="arm_1_link"/>
    <axis xyz="0 0 1"/>
    <calibration rising="0"/>
    <dynamics damping="10"/>
    <limit effort="370" lower="-6.2831853" upper="6.2831853" velocity="2.0"/>
    <safety_controller k_position="20" k_velocity="50" soft_lower_limit="-6.2731853" soft_upper_limit="6.2731853"/>
  </joint>
  <link name="arm_1_link">
    <inertial>
      <origin rpy="0 0 0" xyz="0 0 0"/>
      <mass value="0.29364"/>
      <inertia ixx="0.01" ixy="0" ixz="0" iyy="0.01" iyz="0" izz="0.01"/>
    </inertial>
    <visual>
      <origin rpy="0 0 0" xyz="0 0 0"/>
      <geometry>
        <mesh filename="package://schunk_description/meshes/lwa4p/arm_1_link.stl"/>
      </geometry>
      <material name="Schunk/Blue"/>
    </visual>
    <collision>
      <origin rpy="0 0 0" xyz="0 0 0"/>
      <geometry>
        <mesh filename="package://schunk_description/meshes/lwa4p/arm_1_link.stl"/>
      </geometry>
    </collision>
  </link>
  <joint name="arm_2_joint" type="revolute">
    <origin rpy="1.5708 0 0" xyz="0 0 0"/>
    <parent link="arm_1_link"/>
    <child link="arm_2_link"/>
    <axis xyz="0 0 1"/>
    <calibration rising="0"/>
    <dynamics damping="10"/>
    <limit effort="370" lower="-2.0943951" upper="2.0943951" velocity="2.0"/>
    <safety_controller k_position="20" k_velocity="50" soft_lower_limit="-2.0843" soft_upper_limit="2.0843"/>
  </joint>
  <link name="arm_2_link">
    <inertial>
      <origin rpy="0 0 0" xyz="0 0 0"/>
      <mass value="1.68311"/>
      <inertia ixx="0.03" ixy="0" ixz="0" iyy="0.03" iyz="0" izz="0.03"/>
    </inertial>
    <visual>
      <origin rpy="0 0 0" xyz="0 0 0"/>
      <geometry>
        <mesh filename="package://schunk_description/meshes/lwa4p/arm_2_link.stl"/>
      </geometry>
      <material name="Schunk/LightGrey"/>
    </visual>
    <collision>
      <origin rpy="0 0 0" xyz="0 0 0"/>
      <geometry>
        <mesh filename="package://schunk_description/meshes/lwa4p/arm_2_link.stl"/>
      </geometry>
    </collision>
  </link>
  <joint name="arm_3_joint" type="revolute">
    <origin rpy="0 3.14159 0" xyz="0 0.350 0"/>
    <parent link="arm_2_link"/>
    <child link="arm_3_link"/>
    <axis xyz="0 0 1"/>
    <calibration rising="0"/>
    <dynamics damping="5"/>
    <limit effort="176" lower="-6.2831853" upper="6.2831853" velocity="2.0"/>
    <safety_controller k_position="20" k_velocity="25" soft_lower_limit="-6.2731853" soft_upper_limit="6.2731853"/>
  </joint>
  <link name="arm_3_link">
    <inertial>
      <origin rpy="0 0 0" xyz="0 0 0"/>
      <mass value="2.1"/>
      <inertia ixx="0.03" ixy="0" ixz="0" iyy="0.03" iyz="0" izz="0.03"/>
    </inertial>
    <visual>
      <origin rpy="0 0 0" xyz="0 0 0"/>
      <geometry>
        <mesh filename="package://schunk_description/meshes/lwa4p/arm_3_link.stl"/>
      </geometry>
      <material name="Schunk/Blue"/>
    </visual>
    <collision>
      <origin rpy="0 0 0" xyz="0 0 0"/>
      <geometry>
        <mesh filename="package://schunk_description/meshes/lwa4p/arm_3_link.stl"/>
      </geometry>
    </collision>
  </link>
  <joint name="arm_4_joint" type="revolute">
    <origin rpy="-1.5708 3.14159 0" xyz="0 0 0"/>
    <parent link="arm_3_link"/>
    <child link="arm_4_link"/>
    <axis xyz="0 0 1"/>
    <calibration rising="0"/>
    <dynamics damping="5"/>
    <limit effort="176" lower="-2.0943951" upper="2.0943951" velocity="2.0"/>
    <safety_controller k_position="20" k_velocity="25" soft_lower_limit="-2.0843951" soft_upper_limit="2.0843951"/>
  </joint>
  <link name="arm_4_link">
    <inertial>
      <origin rpy="0 0 0" xyz="0 0 0"/>
      <mass value="1.68311"/>
      <inertia ixx="0.03" ixy="0" ixz="0" iyy="0.03" iyz="0" izz="0.03"/>
    </inertial>
    <visual>
      <origin rpy="0 0 0" xyz="0 0 0"/>
      <geometry>
        <mesh filename="package://schunk_description/meshes/lwa4p/arm_4_link.stl"/>
      </geometry>
      <material name="Schunk/LightGrey"/>
    </visual>
    <collision>
      <origin rpy="0 0 0" xyz="0 0 0"/>
      <geometry>
        <mesh filename="package://schunk_description/meshes/lwa4p/arm_4_link.stl"/>
      </geometry>
    </collision>
  </link>
  <joint name="arm_5_joint" type="revolute">
    <origin rpy="1.5708 0 3.14159" xyz="0 0.005263 0.305"/>
    <parent link="arm_4_link"/>
    <child link="arm_5_link"/>
    <axis xyz="0 0 1"/>
    <calibration rising="0"/>
    <dynamics damping="5"/>
    <limit effort="41.6" lower="-6.2831853" upper="6.2831853" velocity="2.0"/>
    <safety_controller k_position="20" k_velocity="25" soft_lower_limit="-6.2731853" soft_upper_limit="6.2731853"/>
  </joint>
  <link name="arm_5_link">
    <inertial>
      <origin rpy="0 0 0" xyz="0 0 0"/>
      <mass value="0.807"/>
      <inertia ixx="0.03" ixy="0" ixz="0" iyy="0.03" iyz="0" izz="0.03"/>
    </inertial>
    <visual>
      <origin rpy="0 0 0" xyz="0 0 0"/>
      <geometry>
        <mesh filename="package://schunk_description/meshes/lwa4p/arm_5_link.stl"/>
      </geometry>
      <material name="Schunk/Blue"/>
    </visual>
    <collision>
      <origin rpy="0 0 0" xyz="0 0 0"/>
      <geometry>
        <mesh filename="package://schunk_description/meshes/lwa4p/arm_5_link.stl"/>
      </geometry>
    </collision>
  </link>
  <joint name="arm_6_joint" type="revolute">
    <origin rpy="-1.5708 0 0" xyz="0 0 0"/>
    <parent link="arm_5_link"/>
    <child link="arm_6_link"/>
    <axis xyz="0 0 1"/>
    <calibration rising="0"/>
    <dynamics damping="5"/>
    <limit effort="20.1" lower="-2.0943951" upper="2.0943951" velocity="2.0"/>
    <safety_controller k_position="20" k_velocity="25" soft_lower_limit="-2.0843951" soft_upper_limit="2.0843951"/>
  </joint>
  <link name="arm_6_link">
    <inertial>
      <origin rpy="0 0 0" xyz="0 0 0"/>
      <mass value="0.819"/>
      <inertia ixx="0.01" ixy="0" ixz="0" iyy="0.01" iyz="0" izz="0.01"/>
    </inertial>
    <visual>
      <origin rpy="0 0 0" xyz="0 0 0"/>
      <geometry>
        <mesh filename="package://schunk_description/meshes/lwa4p/arm_6_link.stl"/>
      </geometry>
      <material name="Schunk/LightGrey"/>
    </visual>
    <collision>
      <origin rpy="0 0 0" xyz="0 0 0"/>
      <geometry>
        <mesh filename="package://schunk_description/meshes/lwa4p/arm_6_link.stl"/>
      </geometry>
    </collision>
  </link>
  <gazebo reference="arm_0_link">
    <material value="Schunk/LightGrey"/>
    <turnGravityOff>false</turnGravityOff>
    <selfCollide>true</selfCollide>
  </gazebo>
  <gazebo reference="arm_1_link">
    <material value="Schunk/Blue"/>
    <turnGravityOff>false</turnGravityOff>
    <selfCollide>true</selfCollide>
  </gazebo>
  <gazebo reference="arm_2_link">
    <material value="Schunk/LightGrey"/>
    <turnGravityOff>false</turnGravityOff>
    <selfCollide>true</selfCollide>
  </gazebo>
  <gazebo reference="arm_3_link">
    <material value="Schunk/Blue"/>
    <turnGravityOff>false</turnGravityOff>
    <selfCollide>true</selfCollide>
  </gazebo>
  <gazebo reference="arm_4_link">
    <material value="Schunk/LightGrey"/>
    <turnGravityOff>false</turnGravityOff>
    <selfCollide>true</selfCollide>
  </gazebo>
  <gazebo reference="arm_5_link">
    <material value="Schunk/Blue"/>
    <turnGravityOff>false</turnGravityOff>
    <selfCollide>true</selfCollide>
  </gazebo>
  <gazebo reference="arm_6_link">
    <material value="Schunk/LightGrey"/>
    <turnGravityOff>false</turnGravityOff>
    <selfCollide>true</selfCollide>
  </gazebo>
  <transmission name="arm_1_trans">
    <type>transmission_interface/SimpleTransmission</type>
    <joint name="arm_1_joint"/>
    <actuator name="arm_1_motor">
      <hardwareInterface>EffortJointInterface</hardwareInterface>
      <mechanicalReduction>1</mechanicalReduction>
    </actuator>
  </transmission>
  <transmission name="arm_2_trans">
    <type>transmission_interface/SimpleTransmission</type>
    <joint name="arm_2_joint"/>
    <actuator name="arm_2_motor">
      <hardwareInterface>EffortJointInterface</hardwareInterface>
      <mechanicalReduction>1</mechanicalReduction>
    </actuator>
  </transmission>
  <transmission name="arm_3_trans">
    <type>transmission_interface/SimpleTransmission</type>
    <joint name="arm_3_joint"/>
    <actuator name="arm_3_motor">
      <hardwareInterface>EffortJointInterface</hardwareInterface>
      <mechanicalReduction>1</mechanicalReduction>
    </actuator>
  </transmission>
  <transmission name="arm_4_trans">
    <type>transmission_interface/SimpleTransmission</type>
    <joint name="arm_4_joint"/>
    <actuator name="arm_4_motor">
      <hardwareInterface>EffortJointInterface</hardwareInterface>
      <mechanicalReduction>1</mechanicalReduction>
    </actuator>
  </transmission>
  <transmission name="arm_5_trans">
    <type>transmission_interface/SimpleTransmission</type>
    <joint name="arm_5_joint"/>
    <actuator name="arm_5_motor">
      <hardwareInterface>EffortJointInterface</hardwareInterface>
      <mechanicalReduction>1</mechanicalReduction>
    </actuator>
  </transmission>
  <transmission name="arm_6_trans">
    <type>transmission_interface/SimpleTransmission</type>
    <joint name="arm_6_joint"/>
    <actuator name="arm_6_motor">
      <hardwareInterface>EffortJointInterface</hardwareInterface>
      <mechanicalReduction>1</mechanicalReduction>
    </actuator>
  </transmission>
  <link name="ft45_link">
    <visual>
      <origin rpy="0 0 0" xyz="0 0 -0.025"/>
      <geometry>
        <cylinder length="0.05" radius="0.04"/>
      </geometry>
    </visual>
    <collision>
      <origin rpy="0 0 0" xyz="0 0 -0.025"/>
      <geometry>
        <cylinder length="0.05" radius="0.04"/>
      </geometry>
    </collision>
  </link>
  <joint name="ft45_joint" type="fixed">
    <parent link="arm_6_link"/>
    <child link="ft45_link"/>
    <origin rpy="0 0 0" xyz="0 0 0.13"/>
  </joint>
  <link name="coupler_link">
    <visual>
      <origin rpy="0 0 0" xyz="0 0 -0.002"/>
      <geometry>
        <box size="0.24 0.1 0.002"/>
      </geometry>
    </visual>
    <collision>
      <origin rpy="0 0 0" xyz="0 0 -0.002"/>
      <geometry>
        <box size="0.24 0.1 0.002"/>
      </geometry>
    </collision>
  </link>
  <joint name="coupler_joint" type="fixed">
    <parent link="ft45_link"/>
    <child link="coupler_link"/>
    <origin rpy="0 0 0" xyz="0 0 0.002"/>
  </joint>
  <link name="v_camera_link">
    <visual>
      <origin rpy="0 0 0" xyz="0 0 -0.01"/>
      <geometry>
        <box size="0.03 0.07 0.02"/>
      </geometry>
    </visual>
    <collision>
      <origin rpy="0 0 0" xyz="0 0 -0.01"/>
      <geometry>
        <box size="0.03 0.07 0.02"/>
      </geometry>
    </collision>
  </link>
  <joint name="v_camera_joint" type="fixed">
    <parent link="coupler_link"/>
    <child link="v_camera_link"/>
    <origin rpy="0 0 0" xyz="-0.095 0 0.02"/>
  </joint>
  <link name="tool_link">
    <visual>
      <origin rpy="0 0 0" xyz="0 0 -0.07"/>
      <geometry>
        <cylinder length="0.14" radius="0.03"/>
      </geometry>
    </visual>
    <collision>
      <origin rpy="0 0 0" xyz="0 0 -0.07"/>
      <geometry>
        <cylinder length="0.14" radius="0.03"/>
      </geometry>
    </collision>
  </link>
  <joint name="tool_joint" type="fixed">
    <parent link="coupler_link"/>
    <child link="tool_link"/>
    <origin rpy="0 0 0" xyz="0 0 0.14"/>
  </joint>
  <link name="camera_link_support_axis"/>
  <joint name="camera_link_support_axis_joint" type="fixed">
    <origin rpy="1.5708 0.623 0.0" xyz="-0.02 -0.015 0.0"/>
    <parent link="support_top_link"/>
    <child link="camera_link_support_axis"/>
  </joint>
  <link name="camera_link"/>
  <joint name="camera_link_joint" type="fixed">
    <origin rpy="0 0 0" xyz="0.045 0.06 0.017"/>
    <parent link="camera_link_support_axis"/>
    <child link="camera_link"/>
  </joint>
  <joint name="imu_mpu_9150_joint" type="fixed">
    <axis xyz="1 0 0"/>
    <!-- 0 1 0 -->
    <origin rpy="0 0 0 " xyz="0.0775 0.0 0.1555"/>
    <parent link="base_link"/>
    <child link="imu_mpu_9150_link"/>
  </joint>
  <link name="imu_mpu_9150_link">
    <inertial>
      <mass value="0.001"/>
      <origin rpy="0 0 0" xyz="0 0 0"/>
      <inertia ixx="0.0001" ixy="0" ixz="0" iyy="0.000001" iyz="0" izz="0.0001"/>
    </inertial>
    <visual>
      <origin rpy="0 0 0" xyz="0 0 0"/>
      <geometry>
        <box size="0.001 0.001 0.001"/>
      </geometry>
    </visual>
    <collision>
      <origin rpy="0 0 0" xyz="0 0 0"/>
      <geometry>
        <box size=".001 .001 .001"/>
      </geometry>
    </collision>
  </link>
  <gazebo>
    <plugin filename="libgazebo_ros_imu.so" name="ros_imu">
      <robotNamespace>/guardian</robotNamespace>
      <topicName>imu_data</topicName>
      <bodyName>imu_link </bodyName>
      <serviceName>/imu_service</serviceName>
      <gaussianNoise>0.005</gaussianNoise>
    </plugin>
  </gazebo>
  <link name="imu_link"/>
  <joint name="imu_joint" type="fixed">
    <origin rpy="0 0 0 " xyz="0.056 0.0 0.1355"/>
    <parent link="base_link"/>
    <child link="imu_link"/>
  </joint>
  <link name="hokuyo_front_laser_tilt_support_link">
    <inertial>
      <origin rpy="0 0 0" xyz="0 0 0"/>
      <mass value="0.3"/>
      <inertia ixx="1.0" ixy="0.0" ixz="0.0" iyy="1.0" iyz="0.0" izz="1.0"/>
    </inertial>
  </link>
  <joint name="hokuyo_front_laser_tilt_support_joint" type="fixed">
    <axis xyz="0 1 0"/>
    <origin rpy="0.0 0.0 0.0" xyz="0.46 0.0 0.2535"/>
    <parent link="base_link"/>
    <child link="hokuyo_front_laser_tilt_support_link"/>
    <limit effort="30" lower="-2.6" upper="2.6" velocity="2.0"/>
    <dynamics damping="100"/>
  </joint>
  <link name="hokuyo_front_laser_tilt_axis_link">
    <inertial>
      <origin rpy="0 0 0" xyz="0 0 0"/>
      <mass value="1"/>
      <inertia ixx="0.1" ixy="0" ixz="0" iyy="0.1" iyz="0" izz="0.1"/>
    </inertial>
  </link>
  <joint name="hokuyo_front_laser_tilt_joint" type="revolute">
    <axis xyz="0 1 0"/>
    <origin rpy="0 0 0" xyz="0 0 0"/>
    <parent link="hokuyo_front_laser_tilt_support_link"/>
    <child link="hokuyo_front_laser_tilt_axis_link"/>
    <limit effort="100.0" lower="-1.5708" upper="1.5708" velocity="100.0"/>
    <joint_properties damping="0.1" friction="{ptz_joint_friction}"/>
  </joint>
  <transmission name="joint_front_laser_trans">
    <type>transmission_interface/SimpleTransmission</type>
    <joint name="hokuyo_front_laser_tilt_joint">
      <hardwareInterface>EffortJointInterface</hardwareInterface>
    </joint>
    <actuator name="front_laser_motor">
      <hardwareInterface>EffortJointInterface</hardwareInterface>
      <mechanicalReduction>1.0</mechanicalReduction>
    </actuator>
  </transmission>
  <joint name="hokuyo_front_laser_joint" type="fixed">
    <axis xyz="0 1 0"/>
    <origin rpy="-0.05 0.0 0.0" xyz="0.03 0.0 0.0735"/>
    <parent link="hokuyo_front_laser_tilt_axis_link"/>
    <child link="hokuyo_front_laser_link"/>
  </joint>
  <link name="hokuyo_front_laser_link">
    <inertial>
      <mass value="0.1"/>
      <origin rpy="0 0 0" xyz="0 0 0"/>
      <inertia ixx="0.1" ixy="0" ixz="0" iyy="0.1" iyz="0" izz="0.1"/>
    </inertial>
  </link>
  <gazebo reference="hokuyo_front_laser_link">
    <material>Gazebo/Grey</material>
    <sensor name="front_laser_sensor" type="ray">
      <pose>0 0 0 0 0 0</pose>
      <visualize>true</visualize>
      <update_rate>10</update_rate>
      <!-- rate of 10 for scan time ~ 100 ms -->
      <ray>
        <scan>
          <horizontal>
            <samples>684</samples>
            <!-- 683 steps + 1 -->
            <resolution>1</resolution>
            <min_angle>-2.0943951</min_angle>
            <!-- 240 deg (total) in the front -->
            <max_angle>2.0943951</max_angle>
          </horizontal>
        </scan>
        <range>
          <min>0.10</min>
          <max>5.0</max>
          <!-- 5.0 -->
          <resolution>0.001</resolution>
          <!-- 0.001 -->
        </range>
        <noise>
          <type>gaussian</type>
          <mean>0.0</mean>
          <stddev>0.0033</stddev>
          <!-- 0.0033 -->
        </noise>
      </ray>
      <plugin filename="libgazebo_ros_laser_2D.so" name="front_laser_plugin">
        <topicName>/guardian/laser_tilt_front</topicName>
        <frameName>hokuyo_front_laser_link</frameName>
        <time_increment>0.00009765739</time_increment>
        <!-- time between measurements -->
        <!-- 0.0667 sec /683 steps -->
        <intensities>0</intensities>
        <!-- Whether or not the hokuyo laser returns intensity values. 0 means no intensities[] -->
      </plugin>
    </sensor>
  </gazebo>
  <joint name="hokuyo_back_laser_joint" type="fixed">
    <axis xyz="0 1 0"/>
    <origin rpy="0.12 0.0 3.12659265359" xyz="-0.43 -0.0045 0.3435"/>
    <parent link="base_link"/>
    <child link="hokuyo_back_laser_link"/>
  </joint>
  <link name="hokuyo_back_laser_link">
    <inertial>
      <mass value="0.1"/>
      <origin rpy="0 0 0" xyz="0 0 0"/>
      <inertia ixx="0.1" ixy="0" ixz="0" iyy="0.1" iyz="0" izz="0.1"/>
    </inertial>
    <!-- <inertial> <mass value="1e-5" /> <origin xyz="0 0 0" rpy="0 0 0"/> <inertia ixx="1e-6" ixy="0" ixz="0" iyy="1e-6" iyz="0" izz="1e-6" /> </inertial> -->
  </link>
  <gazebo reference="hokuyo_back_laser_link">
    <material>Gazebo/FlatBlack</material>
    <sensor name="back_laser_sensor" type="ray">
      <pose>0 0 0 0 0 0</pose>
      <visualize>true</visualize>
      <update_rate>10</update_rate>
      <!-- rate of 10 for scan time ~ 100 ms -->
      <ray>
        <scan>
          <horizontal>
            <samples>684</samples>
            <!-- 683 steps + 1 -->
            <resolution>1</resolution>
            <min_angle>-2.0943951</min_angle>
            <!-- 120+120 deg in the back -->
            <max_angle>2.0943951</max_angle>
          </horizontal>
        </scan>
        <range>
          <min>0.10</min>
          <max>5.0</max>
          <!-- 5.0 -->
          <resolution>0.001</resolution>
          <!-- 0.001 -->
        </range>
        <noise>
          <type>gaussian</type>
          <!-- Noise parameters based on published spec for Hokuyo laser achieving "+-30mm" accuracy at range < 10m. A mean of 0.0m and stddev of 0.01m will put 99.7% of samples within 0.03m of the true reading. -->
          <mean>0.0</mean>
          <stddev>0.01</stddev>
          <!-- 0.01 -->
        </noise>
      </ray>
      <plugin filename="libgazebo_ros_laser_2D.so" name="back_laser_plugin">
        <topicName>/guardian/laser_horizontal_back</topicName>
        <frameName>hokuyo_back_laser_link</frameName>
        <time_increment>0.00009765739</time_increment>
        <!-- time between measurements -->
        <!-- 0.0667 sec /683 steps -->
        <intensities>0</intensities>
        <!-- Whether or not the hokuyo laser returns intensity values. 0 means no intensities[] -->
      </plugin>
    </sensor>
  </gazebo>
  <!-- ###### TRACKS ###### -->
  <!-- visual -->
  <link name="left_track">
    <inertial>
      <mass value="1.250"/>
      <origin xyz="0 0 0"/>
      <inertia ixx="0.0109375" ixy="0.0" ixz="0.0" iyy="0.021125" iyz="0.0" izz="0.0109375"/>
      <!-- original -->
    </inertial>
    <visual>
      <origin rpy="0 0 0" xyz="0 0 0"/>
      <geometry>
        <mesh filename="package://guardian_description/meshes/others/v5/trackV5_l.stl"/>
      </geometry>
      <material name="black">
        <color rgba="0.1 0.1 0.1 1"/>
      </material>
    </visual>
  </link>
  <joint name="joint_left_track" type="fixed">
    <parent link="base_link"/>
    <child link="left_track"/>
    <origin rpy="0 0 3.14159265359" xyz="0.0 0.0 0.0"/>
  </joint>
  <gazebo reference="left_track">
    <material>Gazebo/FlatBlack</material>
    <turnGravityOff>false</turnGravityOff>
  </gazebo>
  <link name="right_track">
    <inertial>
      <mass value="1.250"/>
      <origin xyz="0 0 0"/>
      <inertia ixx="0.0109375" ixy="0.0" ixz="0.0" iyy="0.021125" iyz="0.0" izz="0.0109375"/>
      <!-- original -->
    </inertial>
    <visual>
      <origin rpy="0 0 0" xyz="0 0 0"/>
      <geometry>
        <mesh filename="package://guardian_description/meshes/others/v5/trackV5_l.stl"/>
      </geometry>
      <material name="black">
        <color rgba="0.1 0.1 0.1 1"/>
      </material>
    </visual>
  </link>
  <joint name="joint_right_track" type="fixed">
    <parent link="base_link"/>
    <child link="right_track"/>
    <origin rpy="0 0 0" xyz="0.0 0.0 0.0"/>
  </joint>
  <gazebo reference="right_track">
    <material>Gazebo/FlatBlack</material>
    <turnGravityOff>false</turnGravityOff>
  </gazebo>
  <!-- right track collision -->
  <link name="right_tw_1">
    <inertial>
      <mass value="0.25"/>
      <!-- 4.5 -->
      <origin rpy="0 0 0" xyz="0 0 0"/>
      <inertia ixx="0.059" ixy="0.0" ixz="0.0" iyy="0.055" iyz="0.0" izz="0.059"/>
      <!-- <inertia ixx="0.00012411765597" ixy="0.0" ixz="0.0" -->
      <!-- iyy="0.00015218160428" iyz="0.0" -->
      <!-- izz="0.00011763977943" /> -->
      <!-- <inertia ixx="${(1/12)*mass*(3*simple_wheel_radius * simple_wheel_radius + simple_wheel_length*simple_wheel_length)}" ixy="0.0" ixz="0.0" -->
      <!-- iyy="${(1/12)*mass*(3*simple_wheel_radius * simple_wheel_radius + simple_wheel_length*simple_wheel_length)}" iyz="0.0" -->
      <!-- izz="${0.5*mass*(simple_wheel_radius * simple_wheel_radius)}" /> wikipedia formula -->
    </inertial>
    <!-- <visual> -->
    <!-- <origin xyz="0 ${reflect_y * wheel_origin_y} 0" rpy="${PI/2} 0 ${origin_yaw}" /> -->
    <!-- <geometry> -->
    <!-- <cylinder length="${simple_wheel_length}" radius="${simple_wheel_radius}"/> -->
    <!-- </geometry> -->
    <!-- <material name="black"> -->
    <!-- <color rgba="0.1 0.1 0.1 1"/> -->
    <!-- </material> -->
    <!-- </visual> -->
    <collision>
      <origin rpy="1.57079632679 0 0" xyz="0 0 0"/>
      <geometry>
        <cylinder length="0.05" radius="0.15"/>
      </geometry>
      <!-- <material name="black"/> -->
    </collision>
  </link>
  <joint name="joint_right_tw_1" type="continuous">
    <parent link="right_track"/>
    <child link="right_tw_1"/>
    <origin rpy="0 0 0" xyz="0.3 -0.224 0.081"/>
    <axis rpy="0 0 0" xyz="0 1 0"/>
    <limit effort="200.0" velocity="200.0"/>
    <joint_properties damping="0.0" friction="{wheel_joint_friction}"/>
  </joint>
  <transmission name="joint_right_tw_1_trans">
    <type>transmission_interface/SimpleTransmission</type>
    <joint name="joint_right_tw_1"/>
    <actuator name="joint_right_tw_1_motor">
      <hardwareInterface>EffortJointInterface</hardwareInterface>
      <!-- hardwareInterface>VelocityJointInterface</hardwareInterface -->
      <mechanicalReduction>1.0</mechanicalReduction>
      <!-- motorTorqueConstant>1</motorTorqueConstant -->
    </actuator>
  </transmission>
  <gazebo reference="right_tw_1">
    <!-- <material>Gazebo/Grey</material> -->
    <turnGravityOff>false</turnGravityOff>
    <mu1 value="0.95"/>
    <mu2 value="0.85"/>
    <kp value="950000"/>
    <kd value="15"/>
  </gazebo>
  <link name="right_tw_2">
    <inertial>
      <mass value="0.25"/>
      <!-- 4.5 -->
      <origin rpy="0 0 0" xyz="0 0 0"/>
      <inertia ixx="0.059" ixy="0.0" ixz="0.0" iyy="0.055" iyz="0.0" izz="0.059"/>
      <!-- <inertia ixx="0.00012411765597" ixy="0.0" ixz="0.0" -->
      <!-- iyy="0.00015218160428" iyz="0.0" -->
      <!-- izz="0.00011763977943" /> -->
      <!-- <inertia ixx="${(1/12)*mass*(3*simple_wheel_radius * simple_wheel_radius + simple_wheel_length*simple_wheel_length)}" ixy="0.0" ixz="0.0" -->
      <!-- iyy="${(1/12)*mass*(3*simple_wheel_radius * simple_wheel_radius + simple_wheel_length*simple_wheel_length)}" iyz="0.0" -->
      <!-- izz="${0.5*mass*(simple_wheel_radius * simple_wheel_radius)}" /> wikipedia formula -->
    </inertial>
    <!-- <visual> -->
    <!-- <origin xyz="0 ${reflect_y * wheel_origin_y} 0" rpy="${PI/2} 0 ${origin_yaw}" /> -->
    <!-- <geometry> -->
    <!-- <cylinder length="${simple_wheel_length}" radius="${simple_wheel_radius}"/> -->
    <!-- </geometry> -->
    <!-- <material name="black"> -->
    <!-- <color rgba="0.1 0.1 0.1 1"/> -->
    <!-- </material> -->
    <!-- </visual> -->
    <collision>
      <origin rpy="1.57079632679 0 0" xyz="0 0 0"/>
      <geometry>
        <cylinder length="0.05" radius="0.15"/>
      </geometry>
      <!-- <material name="black"/> -->
    </collision>
  </link>
  <joint name="joint_right_tw_2" type="continuous">
    <parent link="right_track"/>
    <child link="right_tw_2"/>
    <origin rpy="0 0 0" xyz="0.15 -0.224 0.081"/>
    <axis rpy="0 0 0" xyz="0 1 0"/>
    <limit effort="200.0" velocity="200.0"/>
    <joint_properties damping="0.0" friction="{wheel_joint_friction}"/>
  </joint>
  <transmission name="joint_right_tw_2_trans">
    <type>transmission_interface/SimpleTransmission</type>
    <joint name="joint_right_tw_2"/>
    <actuator name="joint_right_tw_2_motor">
      <hardwareInterface>EffortJointInterface</hardwareInterface>
      <!-- hardwareInterface>VelocityJointInterface</hardwareInterface -->
      <mechanicalReduction>1.0</mechanicalReduction>
      <!-- motorTorqueConstant>1</motorTorqueConstant -->
    </actuator>
  </transmission>
  <gazebo reference="right_tw_2">
    <!-- <material>Gazebo/Grey</material> -->
    <turnGravityOff>false</turnGravityOff>
    <mu1 value="0.95"/>
    <mu2 value="0.85"/>
    <kp value="950000"/>
    <kd value="15"/>
  </gazebo>
  <link name="right_tw_3">
    <inertial>
      <mass value="0.25"/>
      <!-- 4.5 -->
      <origin rpy="0 0 0" xyz="0 0 0"/>
      <inertia ixx="0.059" ixy="0.0" ixz="0.0" iyy="0.055" iyz="0.0" izz="0.059"/>
      <!-- <inertia ixx="0.00012411765597" ixy="0.0" ixz="0.0" -->
      <!-- iyy="0.00015218160428" iyz="0.0" -->
      <!-- izz="0.00011763977943" /> -->
      <!-- <inertia ixx="${(1/12)*mass*(3*simple_wheel_radius * simple_wheel_radius + simple_wheel_length*simple_wheel_length)}" ixy="0.0" ixz="0.0" -->
      <!-- iyy="${(1/12)*mass*(3*simple_wheel_radius * simple_wheel_radius + simple_wheel_length*simple_wheel_length)}" iyz="0.0" -->
      <!-- izz="${0.5*mass*(simple_wheel_radius * simple_wheel_radius)}" /> wikipedia formula -->
    </inertial>
    <!-- <visual> -->
    <!-- <origin xyz="0 ${reflect_y * wheel_origin_y} 0" rpy="${PI/2} 0 ${origin_yaw}" /> -->
    <!-- <geometry> -->
    <!-- <cylinder length="${simple_wheel_length}" radius="${simple_wheel_radius}"/> -->
    <!-- </geometry> -->
    <!-- <material name="black"> -->
    <!-- <color rgba="0.1 0.1 0.1 1"/> -->
    <!-- </material> -->
    <!-- </visual> -->
    <collision>
      <origin rpy="1.57079632679 0 0" xyz="0 0 0"/>
      <geometry>
        <cylinder length="0.05" radius="0.15"/>
      </geometry>
      <!-- <material name="black"/> -->
    </collision>
  </link>
  <joint name="joint_right_tw_3" type="continuous">
    <parent link="right_track"/>
    <child link="right_tw_3"/>
    <origin rpy="0 0 0" xyz="0 -0.224 0.081"/>
    <axis rpy="0 0 0" xyz="0 1 0"/>
    <limit effort="200.0" velocity="200.0"/>
    <joint_properties damping="0.0" friction="{wheel_joint_friction}"/>
  </joint>
  <transmission name="joint_right_tw_3_trans">
    <type>transmission_interface/SimpleTransmission</type>
    <joint name="joint_right_tw_3"/>
    <actuator name="joint_right_tw_3_motor">
      <hardwareInterface>EffortJointInterface</hardwareInterface>
      <!-- hardwareInterface>VelocityJointInterface</hardwareInterface -->
      <mechanicalReduction>1.0</mechanicalReduction>
      <!-- motorTorqueConstant>1</motorTorqueConstant -->
    </actuator>
  </transmission>
  <gazebo reference="right_tw_3">
    <!-- <material>Gazebo/Grey</material> -->
    <turnGravityOff>false</turnGravityOff>
    <mu1 value="0.95"/>
    <mu2 value="0.85"/>
    <kp value="950000"/>
    <kd value="15"/>
  </gazebo>
  <link name="right_tw_4">
    <inertial>
      <mass value="0.25"/>
      <!-- 4.5 -->
      <origin rpy="0 0 0" xyz="0 0 0"/>
      <inertia ixx="0.059" ixy="0.0" ixz="0.0" iyy="0.055" iyz="0.0" izz="0.059"/>
      <!-- <inertia ixx="0.00012411765597" ixy="0.0" ixz="0.0" -->
      <!-- iyy="0.00015218160428" iyz="0.0" -->
      <!-- izz="0.00011763977943" /> -->
      <!-- <inertia ixx="${(1/12)*mass*(3*simple_wheel_radius * simple_wheel_radius + simple_wheel_length*simple_wheel_length)}" ixy="0.0" ixz="0.0" -->
      <!-- iyy="${(1/12)*mass*(3*simple_wheel_radius * simple_wheel_radius + simple_wheel_length*simple_wheel_length)}" iyz="0.0" -->
      <!-- izz="${0.5*mass*(simple_wheel_radius * simple_wheel_radius)}" /> wikipedia formula -->
    </inertial>
    <!-- <visual> -->
    <!-- <origin xyz="0 ${reflect_y * wheel_origin_y} 0" rpy="${PI/2} 0 ${origin_yaw}" /> -->
    <!-- <geometry> -->
    <!-- <cylinder length="${simple_wheel_length}" radius="${simple_wheel_radius}"/> -->
    <!-- </geometry> -->
    <!-- <material name="black"> -->
    <!-- <color rgba="0.1 0.1 0.1 1"/> -->
    <!-- </material> -->
    <!-- </visual> -->
    <collision>
      <origin rpy="1.57079632679 0 0" xyz="0 0 0"/>
      <geometry>
        <cylinder length="0.05" radius="0.15"/>
      </geometry>
      <!-- <material name="black"/> -->
    </collision>
  </link>
  <joint name="joint_right_tw_4" type="continuous">
    <parent link="right_track"/>
    <child link="right_tw_4"/>
    <origin rpy="0 0 0" xyz="-0.15 -0.224 0.081"/>
    <axis rpy="0 0 0" xyz="0 1 0"/>
    <limit effort="200.0" velocity="200.0"/>
    <joint_properties damping="0.0" friction="{wheel_joint_friction}"/>
  </joint>
  <transmission name="joint_right_tw_4_trans">
    <type>transmission_interface/SimpleTransmission</type>
    <joint name="joint_right_tw_4"/>
    <actuator name="joint_right_tw_4_motor">
      <hardwareInterface>EffortJointInterface</hardwareInterface>
      <!-- hardwareInterface>VelocityJointInterface</hardwareInterface -->
      <mechanicalReduction>1.0</mechanicalReduction>
      <!-- motorTorqueConstant>1</motorTorqueConstant -->
    </actuator>
  </transmission>
  <gazebo reference="right_tw_4">
    <!-- <material>Gazebo/Grey</material> -->
    <turnGravityOff>false</turnGravityOff>
    <mu1 value="0.95"/>
    <mu2 value="0.85"/>
    <kp value="950000"/>
    <kd value="15"/>
  </gazebo>
  <link name="right_tw_5">
    <inertial>
      <mass value="0.25"/>
      <!-- 4.5 -->
      <origin rpy="0 0 0" xyz="0 0 0"/>
      <inertia ixx="0.059" ixy="0.0" ixz="0.0" iyy="0.055" iyz="0.0" izz="0.059"/>
      <!-- <inertia ixx="0.00012411765597" ixy="0.0" ixz="0.0" -->
      <!-- iyy="0.00015218160428" iyz="0.0" -->
      <!-- izz="0.00011763977943" /> -->
      <!-- <inertia ixx="${(1/12)*mass*(3*simple_wheel_radius * simple_wheel_radius + simple_wheel_length*simple_wheel_length)}" ixy="0.0" ixz="0.0" -->
      <!-- iyy="${(1/12)*mass*(3*simple_wheel_radius * simple_wheel_radius + simple_wheel_length*simple_wheel_length)}" iyz="0.0" -->
      <!-- izz="${0.5*mass*(simple_wheel_radius * simple_wheel_radius)}" /> wikipedia formula -->
    </inertial>
    <!-- <visual> -->
    <!-- <origin xyz="0 ${reflect_y * wheel_origin_y} 0" rpy="${PI/2} 0 ${origin_yaw}" /> -->
    <!-- <geometry> -->
    <!-- <cylinder length="${simple_wheel_length}" radius="${simple_wheel_radius}"/> -->
    <!-- </geometry> -->
    <!-- <material name="black"> -->
    <!-- <color rgba="0.1 0.1 0.1 1"/> -->
    <!-- </material> -->
    <!-- </visual> -->
    <collision>
      <origin rpy="1.57079632679 0 0" xyz="0 0 0"/>
      <geometry>
        <cylinder length="0.05" radius="0.15"/>
      </geometry>
      <!-- <material name="black"/> -->
    </collision>
  </link>
  <joint name="joint_right_tw_5" type="continuous">
    <parent link="right_track"/>
    <child link="right_tw_5"/>
    <origin rpy="0 0 0" xyz="-0.3 -0.224 0.081"/>
    <axis rpy="0 0 0" xyz="0 1 0"/>
    <limit effort="200.0" velocity="200.0"/>
    <joint_properties damping="0.0" friction="{wheel_joint_friction}"/>
  </joint>
  <transmission name="joint_right_tw_5_trans">
    <type>transmission_interface/SimpleTransmission</type>
    <joint name="joint_right_tw_5"/>
    <actuator name="joint_right_tw_5_motor">
      <hardwareInterface>EffortJointInterface</hardwareInterface>
      <!-- hardwareInterface>VelocityJointInterface</hardwareInterface -->
      <mechanicalReduction>1.0</mechanicalReduction>
      <!-- motorTorqueConstant>1</motorTorqueConstant -->
    </actuator>
  </transmission>
  <gazebo reference="right_tw_5">
    <!-- <material>Gazebo/Grey</material> -->
    <turnGravityOff>false</turnGravityOff>
    <mu1 value="0.95"/>
    <mu2 value="0.85"/>
    <kp value="950000"/>
    <kd value="15"/>
  </gazebo>
  <!-- left track collision -->
  <link name="left_tw_1">
    <inertial>
      <mass value="0.25"/>
      <!-- 4.5 -->
      <origin rpy="0 0 3.14159265359" xyz="0 0 0"/>
      <inertia ixx="0.059" ixy="0.0" ixz="0.0" iyy="0.055" iyz="0.0" izz="0.059"/>
      <!-- <inertia ixx="0.00012411765597" ixy="0.0" ixz="0.0" -->
      <!-- iyy="0.00015218160428" iyz="0.0" -->
      <!-- izz="0.00011763977943" /> -->
      <!-- <inertia ixx="${(1/12)*mass*(3*simple_wheel_radius * simple_wheel_radius + simple_wheel_length*simple_wheel_length)}" ixy="0.0" ixz="0.0" -->
      <!-- iyy="${(1/12)*mass*(3*simple_wheel_radius * simple_wheel_radius + simple_wheel_length*simple_wheel_length)}" iyz="0.0" -->
      <!-- izz="${0.5*mass*(simple_wheel_radius * simple_wheel_radius)}" /> wikipedia formula -->
    </inertial>
    <!-- <visual> -->
    <!-- <origin xyz="0 ${reflect_y * wheel_origin_y} 0" rpy="${PI/2} 0 ${origin_yaw}" /> -->
    <!-- <geometry> -->
    <!-- <cylinder length="${simple_wheel_length}" radius="${simple_wheel_radius}"/> -->
    <!-- </geometry> -->
    <!-- <material name="black"> -->
    <!-- <color rgba="0.1 0.1 0.1 1"/> -->
    <!-- </material> -->
    <!-- </visual> -->
    <collision>
      <origin rpy="1.57079632679 0 3.14159265359" xyz="0 0 0"/>
      <geometry>
        <cylinder length="0.05" radius="0.15"/>
      </geometry>
      <!-- <material name="black"/> -->
    </collision>
  </link>
  <joint name="joint_left_tw_1" type="continuous">
    <parent link="left_track"/>
    <child link="left_tw_1"/>
    <origin rpy="0 0 3.14159265359" xyz="0.3 -0.224 0.081"/>
    <axis rpy="0 0 0" xyz="0 1 0"/>
    <limit effort="200.0" velocity="200.0"/>
    <joint_properties damping="0.0" friction="{wheel_joint_friction}"/>
  </joint>
  <transmission name="joint_left_tw_1_trans">
    <type>transmission_interface/SimpleTransmission</type>
    <joint name="joint_left_tw_1"/>
    <actuator name="joint_left_tw_1_motor">
      <hardwareInterface>EffortJointInterface</hardwareInterface>
      <!-- hardwareInterface>VelocityJointInterface</hardwareInterface -->
      <mechanicalReduction>1.0</mechanicalReduction>
      <!-- motorTorqueConstant>1</motorTorqueConstant -->
    </actuator>
  </transmission>
  <gazebo reference="left_tw_1">
    <!-- <material>Gazebo/Grey</material> -->
    <turnGravityOff>false</turnGravityOff>
    <mu1 value="0.95"/>
    <mu2 value="0.85"/>
    <kp value="950000"/>
    <kd value="15"/>
  </gazebo>
  <link name="left_tw_2">
    <inertial>
      <mass value="0.25"/>
      <!-- 4.5 -->
      <origin rpy="0 0 0" xyz="0 0 0"/>
      <inertia ixx="0.059" ixy="0.0" ixz="0.0" iyy="0.055" iyz="0.0" izz="0.059"/>
      <!-- <inertia ixx="0.00012411765597" ixy="0.0" ixz="0.0" -->
      <!-- iyy="0.00015218160428" iyz="0.0" -->
      <!-- izz="0.00011763977943" /> -->
      <!-- <inertia ixx="${(1/12)*mass*(3*simple_wheel_radius * simple_wheel_radius + simple_wheel_length*simple_wheel_length)}" ixy="0.0" ixz="0.0" -->
      <!-- iyy="${(1/12)*mass*(3*simple_wheel_radius * simple_wheel_radius + simple_wheel_length*simple_wheel_length)}" iyz="0.0" -->
      <!-- izz="${0.5*mass*(simple_wheel_radius * simple_wheel_radius)}" /> wikipedia formula -->
    </inertial>
    <!-- <visual> -->
    <!-- <origin xyz="0 ${reflect_y * wheel_origin_y} 0" rpy="${PI/2} 0 ${origin_yaw}" /> -->
    <!-- <geometry> -->
    <!-- <cylinder length="${simple_wheel_length}" radius="${simple_wheel_radius}"/> -->
    <!-- </geometry> -->
    <!-- <material name="black"> -->
    <!-- <color rgba="0.1 0.1 0.1 1"/> -->
    <!-- </material> -->
    <!-- </visual> -->
    <collision>
      <origin rpy="1.57079632679 0 0" xyz="0 0 0"/>
      <geometry>
        <cylinder length="0.05" radius="0.15"/>
      </geometry>
      <!-- <material name="black"/> -->
    </collision>
  </link>
  <joint name="joint_left_tw_2" type="continuous">
    <parent link="left_track"/>
    <child link="left_tw_2"/>
    <origin rpy="0 0 3.14159265359" xyz="0.15 -0.224 0.081"/>
    <axis rpy="0 0 0" xyz="0 1 0"/>
    <limit effort="200.0" velocity="200.0"/>
    <joint_properties damping="0.0" friction="{wheel_joint_friction}"/>
  </joint>
  <transmission name="joint_left_tw_2_trans">
    <type>transmission_interface/SimpleTransmission</type>
    <joint name="joint_left_tw_2"/>
    <actuator name="joint_left_tw_2_motor">
      <hardwareInterface>EffortJointInterface</hardwareInterface>
      <!-- hardwareInterface>VelocityJointInterface</hardwareInterface -->
      <mechanicalReduction>1.0</mechanicalReduction>
      <!-- motorTorqueConstant>1</motorTorqueConstant -->
    </actuator>
  </transmission>
  <gazebo reference="left_tw_2">
    <!-- <material>Gazebo/Grey</material> -->
    <turnGravityOff>false</turnGravityOff>
    <mu1 value="0.95"/>
    <mu2 value="0.85"/>
    <kp value="950000"/>
    <kd value="15"/>
  </gazebo>
  <link name="left_tw_3">
    <inertial>
      <mass value="0.25"/>
      <!-- 4.5 -->
      <origin rpy="0 0 0" xyz="0 0 0"/>
      <inertia ixx="0.059" ixy="0.0" ixz="0.0" iyy="0.055" iyz="0.0" izz="0.059"/>
      <!-- <inertia ixx="0.00012411765597" ixy="0.0" ixz="0.0" -->
      <!-- iyy="0.00015218160428" iyz="0.0" -->
      <!-- izz="0.00011763977943" /> -->
      <!-- <inertia ixx="${(1/12)*mass*(3*simple_wheel_radius * simple_wheel_radius + simple_wheel_length*simple_wheel_length)}" ixy="0.0" ixz="0.0" -->
      <!-- iyy="${(1/12)*mass*(3*simple_wheel_radius * simple_wheel_radius + simple_wheel_length*simple_wheel_length)}" iyz="0.0" -->
      <!-- izz="${0.5*mass*(simple_wheel_radius * simple_wheel_radius)}" /> wikipedia formula -->
    </inertial>
    <!-- <visual> -->
    <!-- <origin xyz="0 ${reflect_y * wheel_origin_y} 0" rpy="${PI/2} 0 ${origin_yaw}" /> -->
    <!-- <geometry> -->
    <!-- <cylinder length="${simple_wheel_length}" radius="${simple_wheel_radius}"/> -->
    <!-- </geometry> -->
    <!-- <material name="black"> -->
    <!-- <color rgba="0.1 0.1 0.1 1"/> -->
    <!-- </material> -->
    <!-- </visual> -->
    <collision>
      <origin rpy="1.57079632679 0 0" xyz="0 0 0"/>
      <geometry>
        <cylinder length="0.05" radius="0.15"/>
      </geometry>
      <!-- <material name="black"/> -->
    </collision>
  </link>
  <joint name="joint_left_tw_3" type="continuous">
    <parent link="left_track"/>
    <child link="left_tw_3"/>
    <origin rpy="0 0 3.14159265359" xyz="0 -0.224 0.081"/>
    <axis rpy="0 0 0" xyz="0 1 0"/>
    <limit effort="200.0" velocity="200.0"/>
    <joint_properties damping="0.0" friction="{wheel_joint_friction}"/>
  </joint>
  <transmission name="joint_left_tw_3_trans">
    <type>transmission_interface/SimpleTransmission</type>
    <joint name="joint_left_tw_3"/>
    <actuator name="joint_left_tw_3_motor">
      <hardwareInterface>EffortJointInterface</hardwareInterface>
      <!-- hardwareInterface>VelocityJointInterface</hardwareInterface -->
      <mechanicalReduction>1.0</mechanicalReduction>
      <!-- motorTorqueConstant>1</motorTorqueConstant -->
    </actuator>
  </transmission>
  <gazebo reference="left_tw_3">
    <!-- <material>Gazebo/Grey</material> -->
    <turnGravityOff>false</turnGravityOff>
    <mu1 value="0.95"/>
    <mu2 value="0.85"/>
    <kp value="950000"/>
    <kd value="15"/>
  </gazebo>
  <link name="left_tw_4">
    <inertial>
      <mass value="0.25"/>
      <!-- 4.5 -->
      <origin rpy="0 0 0" xyz="0 0 0"/>
      <inertia ixx="0.059" ixy="0.0" ixz="0.0" iyy="0.055" iyz="0.0" izz="0.059"/>
      <!-- <inertia ixx="0.00012411765597" ixy="0.0" ixz="0.0" -->
      <!-- iyy="0.00015218160428" iyz="0.0" -->
      <!-- izz="0.00011763977943" /> -->
      <!-- <inertia ixx="${(1/12)*mass*(3*simple_wheel_radius * simple_wheel_radius + simple_wheel_length*simple_wheel_length)}" ixy="0.0" ixz="0.0" -->
      <!-- iyy="${(1/12)*mass*(3*simple_wheel_radius * simple_wheel_radius + simple_wheel_length*simple_wheel_length)}" iyz="0.0" -->
      <!-- izz="${0.5*mass*(simple_wheel_radius * simple_wheel_radius)}" /> wikipedia formula -->
    </inertial>
    <!-- <visual> -->
    <!-- <origin xyz="0 ${reflect_y * wheel_origin_y} 0" rpy="${PI/2} 0 ${origin_yaw}" /> -->
    <!-- <geometry> -->
    <!-- <cylinder length="${simple_wheel_length}" radius="${simple_wheel_radius}"/> -->
    <!-- </geometry> -->
    <!-- <material name="black"> -->
    <!-- <color rgba="0.1 0.1 0.1 1"/> -->
    <!-- </material> -->
    <!-- </visual> -->
    <collision>
      <origin rpy="1.57079632679 0 0" xyz="0 0 0"/>
      <geometry>
        <cylinder length="0.05" radius="0.15"/>
      </geometry>
      <!-- <material name="black"/> -->
    </collision>
  </link>
  <joint name="joint_left_tw_4" type="continuous">
    <parent link="left_track"/>
    <child link="left_tw_4"/>
    <origin rpy="0 0 3.14159265359" xyz="-0.15 -0.224 0.081"/>
    <axis rpy="0 0 0" xyz="0 1 0"/>
    <limit effort="200.0" velocity="200.0"/>
    <joint_properties damping="0.0" friction="{wheel_joint_friction}"/>
  </joint>
  <transmission name="joint_left_tw_4_trans">
    <type>transmission_interface/SimpleTransmission</type>
    <joint name="joint_left_tw_4"/>
    <actuator name="joint_left_tw_4_motor">
      <hardwareInterface>EffortJointInterface</hardwareInterface>
      <!-- hardwareInterface>VelocityJointInterface</hardwareInterface -->
      <mechanicalReduction>1.0</mechanicalReduction>
      <!-- motorTorqueConstant>1</motorTorqueConstant -->
    </actuator>
  </transmission>
  <gazebo reference="left_tw_4">
    <!-- <material>Gazebo/Grey</material> -->
    <turnGravityOff>false</turnGravityOff>
    <mu1 value="0.95"/>
    <mu2 value="0.85"/>
    <kp value="950000"/>
    <kd value="15"/>
  </gazebo>
  <link name="left_tw_5">
    <inertial>
      <mass value="0.25"/>
      <!-- 4.5 -->
      <origin rpy="0 0 0" xyz="0 0 0"/>
      <inertia ixx="0.059" ixy="0.0" ixz="0.0" iyy="0.055" iyz="0.0" izz="0.059"/>
      <!-- <inertia ixx="0.00012411765597" ixy="0.0" ixz="0.0" -->
      <!-- iyy="0.00015218160428" iyz="0.0" -->
      <!-- izz="0.00011763977943" /> -->
      <!-- <inertia ixx="${(1/12)*mass*(3*simple_wheel_radius * simple_wheel_radius + simple_wheel_length*simple_wheel_length)}" ixy="0.0" ixz="0.0" -->
      <!-- iyy="${(1/12)*mass*(3*simple_wheel_radius * simple_wheel_radius + simple_wheel_length*simple_wheel_length)}" iyz="0.0" -->
      <!-- izz="${0.5*mass*(simple_wheel_radius * simple_wheel_radius)}" /> wikipedia formula -->
    </inertial>
    <!-- <visual> -->
    <!-- <origin xyz="0 ${reflect_y * wheel_origin_y} 0" rpy="${PI/2} 0 ${origin_yaw}" /> -->
    <!-- <geometry> -->
    <!-- <cylinder length="${simple_wheel_length}" radius="${simple_wheel_radius}"/> -->
    <!-- </geometry> -->
    <!-- <material name="black"> -->
    <!-- <color rgba="0.1 0.1 0.1 1"/> -->
    <!-- </material> -->
    <!-- </visual> -->
    <collision>
      <origin rpy="1.57079632679 0 0" xyz="0 0 0"/>
      <geometry>
        <cylinder length="0.05" radius="0.15"/>
      </geometry>
      <!-- <material name="black"/> -->
    </collision>
  </link>
  <joint name="joint_left_tw_5" type="continuous">
    <parent link="left_track"/>
    <child link="left_tw_5"/>
    <origin rpy="0 0 3.14159265359" xyz="-0.3 -0.224 0.081"/>
    <axis rpy="0 0 0" xyz="0 1 0"/>
    <limit effort="200.0" velocity="200.0"/>
    <joint_properties damping="0.0" friction="{wheel_joint_friction}"/>
  </joint>
  <transmission name="joint_left_tw_5_trans">
    <type>transmission_interface/SimpleTransmission</type>
    <joint name="joint_left_tw_5"/>
    <actuator name="joint_left_tw_5_motor">
      <hardwareInterface>EffortJointInterface</hardwareInterface>
      <!-- hardwareInterface>VelocityJointInterface</hardwareInterface -->
      <mechanicalReduction>1.0</mechanicalReduction>
      <!-- motorTorqueConstant>1</motorTorqueConstant -->
    </actuator>
  </transmission>
  <gazebo reference="left_tw_5">
    <!-- <material>Gazebo/Grey</material> -->
    <turnGravityOff>false</turnGravityOff>
    <mu1 value="0.95"/>
    <mu2 value="0.85"/>
    <kp value="950000"/>
    <kd value="15"/>
  </gazebo>
  <!-- ###### PLUGIN ###### -->
  <gazebo>
    <!-- from hector_gazebo -->
    <plugin filename="libdiffdrive_plugin_multi_wheel.so" name="diffdrive_plugin_multiwheel">
      <alwaysOn>true</alwaysOn>
      <updateRate>10.0</updateRate>
      <leftJoints>joint_left_tw_1 joint_left_tw_2 joint_left_tw_3 joint_left_tw_4 joint_left_tw_5 </leftJoints>
      <rightJoints>joint_right_tw_1 joint_right_tw_2 joint_right_tw_3 joint_right_tw_4 joint_right_tw_5 </rightJoints>
      <wheelSeparation>0.448</wheelSeparation>
      <wheelDiameter>0.3</wheelDiameter>
      <torque>20</torque>
      <robotBaseFrame>base_footprint</robotBaseFrame>
      <commandTopic>/guardian/cmd_vel</commandTopic>
      <odometryTopic>/guardian/odom</odometryTopic>
      <odometryFrame>odom</odometryFrame>
      <publishOdometryTf>true</publishOdometryTf>
      <publishOdometryMsg>true</publishOdometryMsg>
    </plugin>
  </gazebo>
</robot>
