<?xml version="1.0"?>
<robot name="gwam" 

       xmlns:xi="http://www.w3.org/2001/XInclude"
       xmlns:gazebo="http://playerstage.sourceforge.net/gazebo/xmlschema/#gz"
       xmlns:model="http://playerstage.sourceforge.net/gazebo/xmlschema/#model"
       xmlns:sensor="http://playerstage.sourceforge.net/gazebo/xmlschema/#sensor"
       xmlns:body="http://playerstage.sourceforge.net/gazebo/xmlschema/#body"
       xmlns:geom="http://playerstage.sourceforge.net/gazebo/xmlschema/#geom"
       xmlns:joint="http://playerstage.sourceforge.net/gazebo/xmlschema/#joint"
       xmlns:interface="http://playerstage.sourceforge.net/gazebo/xmlschema/#interface"
       xmlns:rendering="http://playerstage.sourceforge.net/gazebo/xmlschema/#rendering"
       xmlns:renderable="http://playerstage.sourceforge.net/gazebo/xmlschema/#renderable"
       xmlns:controller="http://playerstage.sourceforge.net/gazebo/xmlschema/#controller"
       xmlns:physics="http://playerstage.sourceforge.net/gazebo/xmlschema/#physics">


  <!-- BASE_LINK (DarkGrey) -->
  <link name="base_link">
    <inertial>
      <mass value="15.0" />
      <origin xyz="0 0 0" />
      <inertia  ixx="3.737" ixy="0.008"  ixz="-0.144"  iyy="8.311"  iyz="-0.004"  izz="8.893" />
    </inertial>
    <visual>
       <origin xyz="0 0 0" rpy="0 0 0" />
       <geometry>
	 <mesh filename="package://guardian_description/meshes/chassis/v5/chassisV5_l.stl"/>
       </geometry>
    </visual>
    <collision>
       <origin xyz="0 0 0" rpy="0 0 0 " />
       <geometry>
         <mesh filename="package://guardian_description/meshes/chassis/v5/chassisV5_l.stl"/>
       </geometry>
    </collision>     
  </link>
  <gazebo reference="base_link">
    <material>Gazebo/DarkGrey</material>
    <turnGravityOff>false</turnGravityOff>
  </gazebo>


  <!-- LEFT TRACK (BLACK) -->
  <link name="left_track">
    <inertial>
      <mass value="1.250" />
      <origin xyz="0 0 0" /> 
      <inertia  ixx="0.0109375" ixy="0.0"  ixz="0.0"  iyy="0.021125"  iyz="0.0"  izz="0.0109375" />
    </inertial>
    <visual>
        <origin xyz="0 0 0" rpy="0 0 0" /> 
        <geometry>
	 <mesh filename="package://guardian_description/meshes/others/v5/trackV5_l.stl"/>
        </geometry>
	<material name="black">
  		<color rgba="0.1 0.1 0.1 1"/>
      	</material>
    </visual>
    <collision>
       <origin xyz="0 0 0" rpy="0 0 0" />
       <geometry>
         <mesh filename="package://guardian_description/meshes/others/v5/trackV5_l.stl"/>
       </geometry>
    </collision>
  </link>
  <gazebo reference="left_track">
    <material>Gazebo/FlatBlack</material>
    <turnGravityOff>false</turnGravityOff>
  </gazebo>

  <joint name="joint_left_track" type="fixed">
    <parent link="base_link"/>
    <child link="left_track"/>
    <origin xyz="0.0 0.0 0.0" rpy="0 0 0" /> 
  </joint>


  <!-- RIGHT TRACK (BLACK) -->
  <link name="right_track">
    <inertial>
      <mass value="1.250" />
      <origin xyz="0 0 0" /> 
      <inertia  ixx="0.0109375" ixy="0.0"  ixz="0.0"  iyy="0.021125"  iyz="0.0"  izz="0.0109375" />
    </inertial>
    <visual>
       <origin xyz="0 0 0" rpy="0 0 0" /> 
       <geometry>
	 <mesh filename="package://guardian_description/meshes/others/v5/trackV5_l.stl"/>
       </geometry>
	<material name="black">
		<color rgba="0.1 0.1 0.1 1"/>
      	</material>
    </visual>
    <collision>
       <origin xyz="0 0 0" rpy="0 0 0" />
       <geometry>
         <mesh filename="package://guardian_description/meshes/others/v5/trackV5_l.stl"/>
       </geometry>
    </collision>
  </link>
  <gazebo reference="right_track">
    <material>Gazebo/FlatBlack</material>
    <turnGravityOff>false</turnGravityOff>
  </gazebo>

  <joint name="joint_right_track" type="fixed">
    <parent link="base_link"/>
    <child link="right_track"/>
    <origin xyz="0.0 0.0 0.0" rpy="0 0 3.1415926535" /> 
  </joint>



  <!-- BACK LEFT WHEEL (GREY) -->
  <link name="back_left_wheel">
    <inertial>
      <mass value="4.5" />
      <origin xyz="0 0 0" /> 
      <inertia  ixx="0.059" ixy="0.0"  ixz="0.0"  iyy="0.055"  iyz="0.0"  izz="0.059" />
    </inertial>
    <visual>
       <origin xyz="0 0 0" rpy="0 0 3.1416" /> 
       <geometry>
	 <mesh filename="package://guardian_description/meshes/wheel.stl"/>
       </geometry>
	<material name="grey">
		<color rgba="0.3 0.3 0.3 1"/>
      	</material>
    </visual>
    <collision>
       <origin xyz="0 0 0" rpy="0 0 0" />
       <geometry>
	 <mesh filename="package://guardian_description/meshes/wheel.stl"/>
       </geometry>
    </collision>
  </link>
  <gazebo reference="back_left_wheel">
    <mu1 value="100.0"/> <!-- 2.0 -->
    <mu2 value="100.0"/> <!-- 0.5 -->
    <fdir1 value="1 0 0"/>
    <material>Gazebo/Grey</material>
    <turnGravityOff>false</turnGravityOff>
  </gazebo>

  <joint name="joint_back_left_wheel" type="fixed">
    <parent link="base_link"/>
    <child link="back_left_wheel"/>
    <origin xyz="-0.30 0.265 0" rpy="0 0 0" /> 
    <axis xyz="0 1 0" rpy="0 0 0" />
    <limit effort="100" velocity="100"/>
    <joint_properties damping="0.0" friction="0.0"/>
  </joint>

  <transmission name="joint_blw_trans" type="pr2_mechanism_model/SimpleTransmission">
     <actuator name="joint_blw_motor" />
     <joint name="joint_back_left_wheel" />
     <mechanicalReduction>1</mechanicalReduction>
     <motorTorqueConstant>1</motorTorqueConstant>
  </transmission>


  <!-- BACK RIGHT WHEEL (BLACK) -->
  <link name="back_right_wheel">
    <inertial>
      <mass value="4.5" />
      <origin xyz="0 0 0" />
      <inertia  ixx="0.059" ixy="0.0"  ixz="0.0"  iyy="0.055"  iyz="0.0"  izz="0.059" />
    </inertial>
    <visual>
       <origin xyz="0 0 0" rpy="0 0 0" /> 
       <geometry>
	 <mesh filename="package://guardian_description/meshes/wheel.stl"/>
       </geometry>
	<material name="gray">
		<color rgba="0.3 0.3 0.3 1"/>
      	</material>
    </visual>
    <collision>
       <origin xyz="0 0 0" rpy="0 0 0" /> 
       <geometry>
	 <mesh filename="package://guardian_description/meshes/wheel.stl"/>
       </geometry>
    </collision>
  </link>
  <gazebo reference="back_right_wheel">
    <mu1 value="100.0"/> <!-- 2.0 -->
    <mu2 value="100.0"/> <!-- 0.5 -->
    <fdir1 value="1 0 0"/>
    <material>Gazebo/Grey</material>
    <turnGravityOff>false</turnGravityOff>
  </gazebo>

  <joint name="joint_back_right_wheel" type="fixed">
    <parent link="base_link"/>
    <child link="back_right_wheel"/>
    <origin xyz="-0.30 -0.265 0" rpy="0 0 0" />
    <axis xyz="0 1 0" />
    <limit effort="100" velocity="100"/>
    <joint_properties damping="0.0" friction="0.0"/>
  </joint>

  <transmission name="joint_brw_trans" type="pr2_mechanism_model/SimpleTransmission">
     <actuator name="joint_brw_motor" />
     <joint name="joint_back_right_wheel" />
     <mechanicalReduction>1</mechanicalReduction>
     <motorTorqueConstant>1</motorTorqueConstant>
  </transmission>

  <!-- FRONT LEFT WHEEL (GREY) -->
  <link name="front_left_wheel">
    <inertial>
      <mass value="4.5" />
      <origin xyz="0 0 0" />
      <inertia  ixx="0.059" ixy="0.0"  ixz="0.0"  iyy="0.055"  iyz="0.0"  izz="0.059" />
    </inertial>
    <visual>
       <origin xyz="0 0 0" rpy="0 0 3.1416" /> 
       <geometry>
	 <mesh filename="package://guardian_description/meshes/wheel.stl"/>
       </geometry>
	<material name="grey">
		<color rgba="0.3 0.3 0.3 1"/>
      	</material>
    </visual>
    <collision>
       <origin xyz="0 0 0" rpy="0 0 0" /> 
       <geometry>
	 <mesh filename="package://guardian_description/meshes/wheel.stl"/>
       </geometry>
    </collision>
  </link>
  <gazebo reference="front_left_wheel">
    <mu1 value="100.0"/> <!-- 2.0 -->
    <mu2 value="100.0"/> <!-- 0.5 -->
    <fdir1 value="1 0 0"/>
    <material>Gazebo/Grey</material>
    <turnGravityOff>false</turnGravityOff>
  </gazebo>

  <joint name="joint_front_left_wheel" type="fixed">
    <parent link="base_link"/>
    <child link="front_left_wheel"/>
    <origin xyz="0.30 0.265 0" rpy="0 0 0" />
    <axis xyz="0 1 0" />
    <limit effort="100" velocity="100"/>
    <joint_properties damping="0.0" friction="0.0"/>
  </joint>

  <transmission name="joint_flw_trans" type="pr2_mechanism_model/SimpleTransmission">
     <actuator name="joint_flw_motor" />
     <joint name="joint_front_left_wheel" />
     <mechanicalReduction>1</mechanicalReduction>
     <motorTorqueConstant>1</motorTorqueConstant>
  </transmission>


  <!-- FRONT RIGHT WHEEL (GREY) -->
  <link name="front_right_wheel">
    <inertial>
      <mass value="4.5" />
      <origin xyz="0 0 0" />
      <inertia  ixx="0.059" ixy="0.0"  ixz="0.0"  iyy="0.055"  iyz="0.0"  izz="0.059" />
    </inertial>
    <visual>
       <origin xyz="0 0 0" rpy="0 0 0" /> 
       <geometry>
	 <mesh filename="package://guardian_description/meshes/wheel.stl"/>
       </geometry>
	<material name="grey">
		<color rgba="0.3 0.3 0.3 1"/>
      	</material>
    </visual>
    <collision>
       <origin xyz="0 0 0" rpy="0 0 0" /> 
       <geometry>
	 <mesh filename="package://guardian_description/meshes/wheel.stl"/>
       </geometry>
    </collision>
  </link>
  <gazebo reference="front_right_wheel">
    <mu1 value="100.0"/> <!-- 2.0 -->
    <mu2 value="100.0"/> <!-- 0.5 -->
    <fdir1 value="1 0 0"/>
    <material>Gazebo/Grey</material>
    <turnGravityOff>false</turnGravityOff>
  </gazebo>

  <joint name="joint_front_right_wheel" type="fixed">
    <parent link="base_link"/>
    <child link="front_right_wheel"/>
    <origin xyz="0.30 -0.265 0" rpy="0 0 0" />
    <axis xyz="0 1 0" />
    <limit effort="100" velocity="100"/>
    <joint_properties damping="0.0" friction="0.0"/>
  </joint>

  <transmission name="joint_frw_trans" type="pr2_mechanism_model/SimpleTransmission">
     <actuator name="joint_frw_motor" />
     <joint name="joint_front_right_wheel" />
     <mechanicalReduction>1</mechanicalReduction>
     <motorTorqueConstant>1</motorTorqueConstant>
  </transmission>


  <!-- HOKUYO SENSOR -->
  <joint name="hokuyo_base_laser_joint" type="fixed">
     <axis xyz="0 1 0" />
     <origin xyz="0.45 0 0.32"/>
     <parent link="base_link"/>
     <child link="hokuyo_base_laser_link"/>
  </joint>
  <link name="hokuyo_base_laser_link" type="laser">
     <inertial>
       <mass value="0.001" />
       <origin xyz="0 0 0" rpy="0 0 0" />
       <inertia ixx="0.0001" ixy="0" ixz="0" iyy="0.000001" iyz="0" izz="0.0001" />
    </inertial>
  </link>
  
  <!-- KINECT SENSOR -->
  <joint name="kinect_joint" type="fixed">
     <axis xyz="0 1 0" />
     <origin xyz="0.39 0 0.38"/>
     <parent link="base_link"/>
     <child link="kinect_link"/>
  </joint>
  <link name="kinect_link" type="laser">
     <inertial>
       <mass value="0.001" />
       <origin xyz="0 0 0" rpy="0 0 0" />
       <inertia ixx="0.0001" ixy="0" ixz="0" iyy="0.000001" iyz="0" izz="0.0001" />
    </inertial>
  </link>
  

  <!-- IMU SENSOR -->
  <joint name="imu_joint" type="fixed">
      <axis xyz="1 0 0"/> <!-- 0 1 0 -->
      <origin xyz="0 0 0.2825"/>
      <parent link="base_link"/>
      <child link="imu_link"/>
  </joint>

  <link name="imu_link">
      <inertial>
        <mass value="0.001"/>
        <origin rpy="0 0 0" xyz="0 0 0"/>
        <inertia ixx="0.0001" ixy="0" ixz="0" iyy="0.000001" iyz="0" izz="0.0001"/>
      </inertial>
      <visual>
        <origin rpy="0 0 0" xyz="0 0 0"/>
        <geometry>
          <box size="0.001 0.001 0.001"/>
        </geometry>
      </visual>
      <collision>
        <origin rpy="0 0 0" xyz="0 0 0"/>
        <geometry>
          <box size=".001 .001 .001"/>
        </geometry>
      </collision>
  </link>


  <!-- WAM ARM -->
 
  <link name="wam_link1">
    <inertial>
      <mass value="2.3936"/>
      <origin rpy="0 0 0" xyz="0.0 0.0 0.0"/>
      <inertia ixx="1.0" ixy="0.0" ixz="0.0" iyy="1.0" iyz="0.0" izz="1.0"/>
    </inertial>
    <visual>
      <origin rpy="0 0 0" xyz="0.0 0.0 0.0"/>
      <geometry name="wam_link1_visual">
        <mesh filename="package://guardian_description/meshes/wam1.stl" scale="1.0 1.0 1.0"/>
      </geometry>
      <material name="Grey">
        <color rgba="0.75 0.75 0.75 1.0"/>
      </material>
    </visual>
    <collision>
      <origin rpy="0 0 0" xyz="0.0 0.0 0.0"/>
      <geometry name="wam_link1_collision">
        <mesh filename="package://guardian_description/meshes/wam1.stl" scale="1.0 1.0 1.0"/>
      </geometry>
      <contact_coefficients kd="1.0" kp="1000.0" mu="0"/>
    </collision>
  </link>
  <gazebo reference="wam_link1">
    <material>Gazebo/White</material>
    <selfCollide>true</selfCollide>
  </gazebo>
  <joint name="j1_joint" type="revolute">
    <parent link="base_link"/>
    <child link="wam_link1"/>
    <origin xyz="0.125 0 0.55" rpy="0 0 0" />
    <axis xyz="0 0 1"/>
    <limit effort="30" lower="-2.6" upper="2.6" velocity="2.0"/>
    <dynamics damping="100"/>
  </joint>
  <transmission name="j1_transmission" type="pr2_mechanism_model/SimpleTransmission">
    <actuator name="j1"/>
    <joint name="j1_joint"/>
    <mechanicalReduction>1</mechanicalReduction>
    <motorTorqueConstant>1</motorTorqueConstant>
  </transmission>
  <link name="wam_link2">
    <inertial>
      <origin rpy="0 0 0" xyz="0 0 0"/>
      <mass value="1.8487"/>
      <inertia ixx="1.0" ixy="0.0" ixz="0.0" iyy="0.1" iyz="0.0" izz="0.1"/>
    </inertial>
    <visual>
      <origin rpy="0 0 0" xyz="0.0 0.0 0.0"/>
      <geometry name="wam_link2_visual">
        <mesh filename="package://guardian_description/meshes/wam2.stl" scale="1.0 1.0 1.0"/>
      </geometry>
      <material name="Grey">
        <color rgba="0.75 0.75 0.75 1.0"/>
      </material>
    </visual>
    <collision>
      <origin rpy="0 0 0" xyz="0.0 0.0 0.0"/>
      <geometry name="wam_link2_collision">
        <mesh filename="package://guardian_description/meshes/wam2.stl" scale="1.0 1.0 1.0"/>
      </geometry>
      <contact_coefficients kd="1.0" kp="1000.0" mu="0"/>
    </collision>
  </link>
  <gazebo reference="wam_link2">
    <material>Gazebo/Grey</material>
    <selfCollide>true</selfCollide>
  </gazebo>
  <joint name="j2_joint" type="revolute">
    <parent link="wam_link1"/>
    <child link="wam_link2"/>
    <origin rpy="0 0 0" xyz="0.0 0.0 0.0"/>
    <axis xyz="0 1 0"/>
    <limit effort="30" lower="-2.0" upper="2.0" velocity="2.0"/>
    <dynamics damping="100"/>
  </joint>
  <transmission name="j2_transmission" type="pr2_mechanism_model/SimpleTransmission">
    <actuator name="j2"/>
    <joint name="j2_joint"/>
    <mechanicalReduction>1</mechanicalReduction>
    <motorTorqueConstant>1</motorTorqueConstant>
    <!--<pulsesPerRevolution>90000</pulsesPerRevolution>-->
  </transmission>
  <link name="wam_link3">
    <inertial>
      <mass value="0.43"/>
      <origin rpy="0 0 0" xyz="0 0 0.225"/>
      <inertia ixx="1.0" ixy="0.0" ixz="0.0" iyy="0.1" iyz="0.0" izz="0.1"/>
    </inertial>
    <visual>
      <origin rpy="0 0 0" xyz="0.0 0.0 0.0"/>
      <geometry name="wam_link3_visual">
        <mesh filename="package://guardian_description/meshes/wam3.stl" scale="1.0 1.0 1.0"/>
      </geometry>
      <material name="Grey">
        <color rgba="0.75 0.75 0.75 1.0"/>
      </material>
    </visual>
    <collision>
      <origin rpy="0 0 0" xyz="0.0 0.0 0.0"/>
      <geometry name="wam_link3_collision">
        <mesh filename="package://guardian_description/meshes/wam3.stl" scale="1.0 1.0 1.0"/>
      </geometry>
      <contact_coefficients kd="1.0" kp="1000.0" mu="0"/>
    </collision>
  </link>
  <gazebo reference="wam_link3">
    <material>Gazebo/Grey</material>
    <selfCollide>true</selfCollide>
  </gazebo>
  <joint name="j3_joint" type="revolute">
    <parent link="wam_link2"/>
    <child link="wam_link3"/>
    <origin rpy="0 0 0" xyz="0.0 0.0 0.0"/>
    <axis xyz="0 0 1"/>
    <limit effort="30" lower="-2.8" upper="2.8" velocity="2.0"/>
    <dynamics damping="100"/>
  </joint>
  <transmission name="j3_transmission" type="pr2_mechanism_model/SimpleTransmission">
    <actuator name="j3"/>
    <joint name="j3_joint"/>
    <mechanicalReduction>1</mechanicalReduction>
    <motorTorqueConstant>1</motorTorqueConstant>
    <!-- <pulsesPerRevolution>90000</pulsesPerRevolution>-->
  </transmission>
  <link name="wam_link4">
    <inertial>
      <mass value="0.52"/>
      <origin rpy="0 0 0" xyz="-0.045 -0.15 0"/>
      <inertia ixx="1.0" ixy="0.0" ixz="0.0" iyy="0.1" iyz="0.0" izz="0.1"/>
    </inertial>
    <visual>
      <origin rpy="0 0 0" xyz="0.0 0.0 0.0"/>
      <geometry name="wam_link4_visual">
        <mesh filename="package://guardian_description/meshes/wam4.stl" scale="1.0 1.0 1.0"/>
      </geometry>
      <material name="Grey">
        <color rgba="0.75 0.75 0.75 1.0"/>
      </material>
    </visual>
    <collision>
      <origin rpy="0 0 0" xyz="0.0 0.0 0.0"/>
      <geometry name="wam_link4_collision">
        <mesh filename="package://guardian_description/meshes/wam4.stl" scale="1.0 1.0 1.0"/>
      </geometry>
      <contact_coefficients kd="1.0" kp="1000.0" mu="0"/>
    </collision>
  </link>
  <gazebo reference="wam_link4">
    <material>Gazebo/Grey</material>
    <selfCollide>true</selfCollide>
  </gazebo>
  <joint name="j4_joint" type="revolute">
    <parent link="wam_link3"/>
    <child link="wam_link4"/>
    <origin rpy="-1.57079632679 0 0" xyz="0.045 0.0 0.55"/>
    <axis xyz="0 0 1"/>
    <limit effort="35" lower="-0.9" upper="2.8" velocity="2.0"/>
    <dynamics damping="100"/>
  </joint>
  <transmission name="j4_transmission" type="pr2_mechanism_model/SimpleTransmission">
    <actuator name="j4"/>
    <joint name="j4_joint"/>
    <mechanicalReduction>1</mechanicalReduction>
    <motorTorqueConstant>1</motorTorqueConstant>
    <!--<pulsesPerRevolution>90000</pulsesPerRevolution>-->
  </transmission>
  <link name="wam_link5">
    <inertial>
      <origin rpy="0 0 0" xyz="0 0 0"/>
      <mass value="0.076675"/>
      <inertia ixx="1.0" ixy="0.0" ixz="0.0" iyy="0.1" iyz="0.0" izz="0.1"/>
    </inertial>
    <visual>
      <origin rpy="0 0 0" xyz="0.0 0.0 0.0"/>
      <geometry name="wam_link5_visual">
        <mesh filename="package://guardian_description/meshes/wam5.stl" scale="1.0 1.0 1.0"/>
      </geometry>
      <material name="Grey">
        <color rgba="0.75 0.75 0.75 1.0"/>
      </material>
    </visual>
    <collision>
      <origin rpy="0 0 0" xyz="0.0 0.0 0.0"/>
      <geometry name="wam_link5_collision">
        <mesh filename="package://guardian_description/meshes/wam5.stl" scale="1.0 1.0 1.0"/>
      </geometry>
      <contact_coefficients kd="1.0" kp="1000.0" mu="0"/>
    </collision>
  </link>
  <gazebo reference="wam_link5">
    <material>Gazebo/Grey</material>
    <selfCollide>true</selfCollide>
  </gazebo>
  <joint name="j5_joint" type="revolute">
    <parent link="wam_link4"/>
    <child link="wam_link5"/>
    <origin rpy="1.57079632679 0 0" xyz="-0.045 -0.3 0.0"/>
    <axis xyz="0 0 1"/>
    <limit effort="30" lower="-4.8" upper="1.3" velocity="2.0"/>
    <dynamics damping="100"/>
  </joint>
  <transmission name="j5_transmission" type="pr2_mechanism_model/SimpleTransmission">
    <actuator name="j5"/>
    <joint name="j5_joint"/>
    <mechanicalReduction>1</mechanicalReduction>
    <motorTorqueConstant>1</motorTorqueConstant>
    <!--  <pulsesPerRevolution>90000</pulsesPerRevolution>-->
  </transmission>
  <link name="wam_link6">
    <inertial>
      <origin rpy="0 0 0" xyz="0 0 0"/>
      <mass value="0.10695"/>
      <inertia ixx="1.0" ixy="0.0" ixz="0.0" iyy="0.1" iyz="0.0" izz="0.1"/>
    </inertial>
    <visual>
      <origin rpy="0 0 0" xyz="0.0 0.0 0.0"/>
      <geometry name="wam_link6_visual">
        <mesh filename="package://guardian_description/meshes/wam6.stl" scale="1.0 1.0 1.0"/>
      </geometry>
      <material name="Grey">
        <color rgba="0.75 0.75 0.75 1.0"/>
      </material>
    </visual>
    <collision>
      <origin rpy="0 0 0" xyz="0.0 0.0 0.0"/>
      <geometry name="wam_link6_collision">
        <mesh filename="package://guardian_description/meshes/wam6.stl" scale="1.0 1.0 1.0"/>
      </geometry>
      <contact_coefficients kd="1.0" kp="1000.0" mu="0"/>
    </collision>
  </link>
  <gazebo reference="wam_link6">
    <material>Gazebo/Grey</material>
    <selfCollide>true</selfCollide>
  </gazebo>
  <joint name="j6_joint" type="revolute">
    <parent link="wam_link5"/>
    <child link="wam_link6"/>
    <origin rpy="-1.57079632679 0 0" xyz="0.0 0.0 0.0"/>
    <axis xyz="0 0 1"/>
    <limit effort="30" lower="-1.6" upper="1.6" velocity="2.0"/>
    <dynamics damping="100"/>
  </joint>
  <transmission name="j6_transmission" type="pr2_mechanism_model/SimpleTransmission">
    <actuator name="j6"/>
    <joint name="j6_joint"/>
    <mechanicalReduction>1</mechanicalReduction>
    <motorTorqueConstant>1</motorTorqueConstant>
    <!--  <pulsesPerRevolution>90000</pulsesPerRevolution>-->
  </transmission>
  <link name="wam_link7">
    <inertial>
      <origin rpy="0 0 0" xyz="0 0 0"/>
      <mass value="0.013925"/>
      <inertia ixx="1.0" ixy="0.0" ixz="0.0" iyy="0.1" iyz="0.0" izz="0.1"/>
    </inertial>
    <visual>
      <origin rpy="0 0 0" xyz="0.0 0.0 0.0"/>
      <geometry name="wam_link7_visual">
        <mesh filename="package://guardian_description/meshes/wam7.stl" scale="1.0 1.0 1.0"/>
      </geometry>
      <material name="Grey">
        <color rgba="0.75 0.75 0.75 1.0"/>
      </material>
    </visual>
    <collision>
      <origin rpy="0 0 0" xyz="0.0 0.0 0.0"/>
      <geometry name="wam_link7_collision">
        <mesh filename="package://guardian_description/meshes/wam7.stl" scale="1.0 1.0 1.0"/>
        <!--                <box size="0.10 0.10 0.10"/> -->
      </geometry>
      <contact_coefficients kd="1.0" kp="1000.0" mu="0"/>
    </collision>
  </link>
  <gazebo reference="wam_link7">
    <material>Gazebo/Grey</material>
    <selfCollide>true</selfCollide>
  </gazebo>
  <joint name="j7_joint" type="revolute">
    <parent link="wam_link6"/>
    <child link="wam_link7"/>
    <origin rpy="1.57079632679 0 0" xyz="0.0 0.0 0.0"/>
    <axis xyz="0 0 1"/>
    <limit effort="30" lower="-2.2" upper="2.2" velocity="2.0"/>
    <!--  <safety_controller k_velocity="0.5"/>-->
    <dynamics damping="100"/>
  </joint>
  <transmission name="j7_transmission" type="pr2_mechanism_model/SimpleTransmission">
    <actuator name="j7"/>
    <joint name="j7_joint"/>
    <mechanicalReduction>1</mechanicalReduction>
    <motorTorqueConstant>1</motorTorqueConstant>
    <!--<pulsesPerRevolution>90000</pulsesPerRevolution>-->
  </transmission>

  <link name="wam_tcp"/>
  <joint name="wamtcp_fix" type="fixed">
    <parent link="wam_link7"/>
    <child link="wam_tcp"/>
    <origin rpy="0 0 0" xyz="0.0 0.0 0.2"/>
  </joint>

  <!-- Gazebo controllers -->
  <gazebo>
     <controller:gazebo_ros_time name="gazebo_ros_time" plugin="libgazebo_ros_time.so">
       <alwaysOn>true</alwaysOn>
       <updateRate>1000.0</updateRate>
       <interface:audio name="dummy_gazebo_ros_time_iface_should_not_be_here"/>
     </controller:gazebo_ros_time>

      <!-- PR2_ACTARRAY -->
     <controller:gazebo_ros_controller_manager name="gazebo_ros_controller_manager" plugin="libgazebo_ros_controller_manager.so">
       <alwaysOn>true</alwaysOn>
       <updateRate>1000.0</updateRate>
       <interface:audio name="gazebo_ros_controller_manager_dummy_iface" />
     </controller:gazebo_ros_controller_manager>

  </gazebo>

  <!-- Other controllers (HOKUYO SENSOR) -->

  <gazebo reference = "hokuyo_base_laser_link">
    <sensor:ray name="hokuyo_laser">
       <rayCount>640</rayCount>
       <rangeCount>640</rangeCount>
       <laserCount>1</laserCount>

       <origin>0.0 0.0 0.0</origin>
       <displayRays>fan</displayRays>

       <minAngle>-120.0</minAngle>
       <maxAngle>120.0</maxAngle>
     
       <minRange>0.05</minRange>
       <maxRange>4.0</maxRange>
       <resRange>0.001</resRange>
       <updateRate>10.0</updateRate>
       <controller:gazebo_ros_laser name="gazebo_ros_hokuyo_laser_controller" plugin="libgazebo_ros_laser.so">
         <gaussianNoise>0.005</gaussianNoise>
         <alwaysOn>true</alwaysOn>
         <updateRate>10.0</updateRate>
         <topicName>hokuyo_laser_topic</topicName>
         <frameName>hokuyo_base_laser_link</frameName>
         <interface:laser name="gazebo_ros_hokuyo_laser_iface" />
       </controller:gazebo_ros_laser>
    </sensor:ray>
   </gazebo>

   <!-- Other controllers (IMU SENSOR) -->

  <gazebo>
    <controller:gazebo_ros_imu name="imu_controller" plugin="libgazebo_ros_imu.so">
      <alwaysOn>true</alwaysOn>
      <updateRate>50.0</updateRate> <!-- 100 -->
      <bodyName>imu_link</bodyName>
      <topicName>imu_data</topicName>
      <gaussianNoise>2.89e-08</gaussianNoise>
      <xyzOffsets>0 0 0</xyzOffsets>
      <rpyOffsets>0 0 0</rpyOffsets>
      <interface:position name="imu_position"/>
    </controller:gazebo_ros_imu>
  </gazebo>
  
  
  <!-- Other controllers (KINECT SENSOR) -->
  <!--gazebo reference="kinect_link">
    <sensor:camera name="camera">
      <imageFormat>R8G8B8</imageFormat>
      <imageSize>640 480</imageSize>
      <hfov>60</hfov>
      <nearClip>0.05</nearClip>
      <farClip>3</farClip>
      <updateRate>20</updateRate>
      <baseline>0.1</baseline>
      <controller:gazebo_ros_openni_kinect name="kinect_camera_controller" plugin="libgazebo_ros_openni_kinect.so">
        <cameraName>kinect_camera</cameraName>
        <alwaysOn>true</alwaysOn>
        <updateRate>20</updateRate>
        <imageTopicName>/kinect/image_raw</imageTopicName>
        <pointCloudTopicName>/kinect/depth/points</pointCloudTopicName>
        <cameraInfoTopicName>/kinect/camera_info</cameraInfoTopicName>
        <frameName>kinect_link</frameName>
        <distortion_k1>0.0</distortion_k1>
        <distortion_k2>0.0</distortion_k2>
        <distortion_k3>0.0</distortion_k3>
        <distortion_t1>0.0</distortion_t1>
        <distortion_t2>0.0</distortion_t2>
      </controller:gazebo_ros_openni_kinect>
    </sensor:camera>
  </gazebo-->
  
</robot>
