<?xml version="1.0"?>
<robot xmlns:xacro="http://www.ros.org/wiki/xacro">

	<!-- Robot parameters -->
	<xacro:property name="PI" value="3.1415926535897931" />
	<xacro:property name="ptz_joint_effort_limit" value="30.0" />
	<xacro:property name="ptz_joint_velocity_limit" value="2.0" />
	<xacro:property name="ptz_joint_friction" value="0.1" />
	<xacro:property name="ptz_joint_damping" value="0.1" />
	<xacro:property name="ptz_mechanical_reduction" value="1.0" />


	<xacro:macro name="sensor_hokuyo_front" params="parent prefix visualize support_x support_y support_z support_roll support_pitch support_yaw sensor_x sensor_y sensor_z sensor_roll sensor_pitch sensor_yaw"> <!-- sensor -> laser rotation axis center -->
		<!-- front laser tilting platform -->
		<link name="hokuyo_${prefix}_tilt_support_link" >
			<inertial>
				<origin xyz="0 0 0" rpy="0 0 0" />
				<mass value="0.3" />
				<inertia ixx="1.0" ixy="0.0" ixz="0.0" iyy="1.0" iyz="0.0" izz="1.0" />
			</inertial>
		</link>
		
		<joint name="hokuyo_${prefix}_tilt_support_joint" type="fixed">
			<axis xyz="0 1 0" />
			<origin xyz="${support_x} ${support_y} ${support_z}" rpy="${support_roll} ${support_pitch} ${support_yaw}" />
			<parent link="${parent}" />
			<child link="hokuyo_${prefix}_tilt_support_link" />
			<limit effort="30" lower="-2.6" upper="2.6" velocity="2.0"/>
		 	<dynamics damping="100"/>
		</joint>
		
		
		<!-- front laser tilting platform motor -->
		<link name="hokuyo_${prefix}_tilt_axis_link" >
			<inertial>
				<origin xyz="0 0 0" rpy="0 0 0" />
				<mass value="1" />
				<inertia ixx="0.1" ixy="0" ixz="0" iyy="0.1" iyz="0" izz="0.1" />
			</inertial>
		</link>
		
		<joint name="hokuyo_${prefix}_tilt_joint" type="revolute">
			<axis xyz="0 1 0" />
			<origin xyz="0 0 0" rpy="0 0 0" />
			<parent link="hokuyo_${prefix}_tilt_support_link" />
			<child link="hokuyo_${prefix}_tilt_axis_link" />
			<limit effort="${ptz_joint_effort_limit}" velocity="${ptz_joint_velocity_limit}" lower="-1.5708" upper="1.5708" />
			<joint_properties damping="${ptz_joint_damping}" friction="{ptz_joint_friction}" />
		</joint>

		<transmission name="joint_${prefix}_trans">
			<type>transmission_interface/SimpleTransmission</type>
			<joint name="hokuyo_${prefix}_tilt_joint" >
				<hardwareInterface>EffortJointInterface</hardwareInterface>
			</joint>
			<actuator name="${prefix}_motor">
				<hardwareInterface>EffortJointInterface</hardwareInterface>
				<mechanicalReduction>${ptz_mechanical_reduction}</mechanicalReduction>
			</actuator>
		</transmission>


		<!-- front laser -->
		<joint name="hokuyo_${prefix}_joint" type="fixed">
			<axis xyz="0 1 0" />
			<origin xyz="${sensor_x} ${sensor_y} ${sensor_z}" rpy="${sensor_roll} ${sensor_pitch} ${sensor_yaw}" />
			<parent link="hokuyo_${prefix}_tilt_axis_link" />
			<child link="hokuyo_${prefix}_link" />
		</joint>

		<link name="hokuyo_${prefix}_link">
			<inertial>
				<mass value="0.1" />
				<origin xyz="0 0 0" rpy="0 0 0" />
				<inertia ixx="0.1" ixy="0" ixz="0" iyy="0.1" iyz="0" izz="0.1" />
			</inertial>
		</link>


		<!-- GAZEBO properties and plugins -->
		<gazebo reference="hokuyo_${prefix}_link">
			<material>Gazebo/Grey</material>
			<sensor type="gpu_ray" name="${prefix}_sensor">
				<pose>0 0 0 0 0 0</pose>
				<visualize>${visualize}</visualize>
				<update_rate>10</update_rate> <!-- rate of 10 for scan time ~ 100 ms -->
				<ray>
					<scan>
						<horizontal>
							<samples>684</samples> <!-- 683 steps + 1 -->
							<resolution>1</resolution>
							<min_angle>-2.0943951</min_angle>   <!-- 240 deg (total) in the front -->
							<max_angle>2.0943951</max_angle>
						</horizontal>
					</scan>
					<range>
						<min>0.10</min>
						<max>5.0</max> <!-- 5.0 -->
						<resolution>0.001</resolution> <!-- 0.001 -->
					</range>
					<noise>
						<type>gaussian</type>
						<mean>0.0</mean>
						<stddev>0.0033</stddev> <!-- 0.0033 -->
					</noise>
				</ray>
				<plugin name="${prefix}_plugin" filename="libgazebo_ros_gpu_laser.so">
					<topicName>/guardian/laser_tilt_front</topicName>
					<frameName>hokuyo_${prefix}_link</frameName>
					<time_increment>0.00009765739</time_increment> <!-- time between measurements --> <!-- 0.0667 sec /683 steps -->
					<intensities>0</intensities> <!-- Whether or not the hokuyo laser returns intensity values. 0 means no intensities[] -->
				</plugin>
			</sensor>
		</gazebo>

	</xacro:macro>
</robot>

